Workbook

Sheet marketing_data
A1: ID | B1: Year_Birth | C1: Education | D1: Marital_Status | E1: Income | F1: Kidhome | G1: Teenhome | H1: Dt_Customer | I1: Recency | J1: MntWines | K1: MntFruits | L1: MntMeatProducts | M1: MntFishProducts | N1: MntSweetProducts | O1: MntGoldProds | P1: NumDealsPurchases | Q1: NumWebPurchases | R1: NumCatalogPurchases | S1: NumStorePurchases | T1: NumWebVisitsMonth | U1: AcceptedCmp3 | V1: AcceptedCmp4 | W1: AcceptedCmp5 | X1: AcceptedCmp1 | Y1: AcceptedCmp2 | Z1: Response | AA1: Complain | AB1: Country | AC1: Age | AD1: Total Spend | AE1: Total Purchases
A2: 1826 | B2: 1970 | C2: Graduation | D2: Divorced | E2: 84835 | F2: 0 | G2: 0 | H2: 41806 | I2: 0 | J2: 189 | K2: 104 | L2: 379 | M2: 111 | N2: 189 | O2: 218 | P2: 1 | Q2: 4 | R2: 4 | S2: 6 | T2: 1 | U2: 0 | V2: 0 | W2: 0 | X2: 0 | Y2: 0 | Z2: 1 | AA2: 0 | AB2: Spain | AC2: =YEAR(TODAY()) - B2 -> 56 | AD2: =SUM(J2:O2) -> 1190 | AE2: =SUM(P2:T2) -> 16
A3: 1 | B3: 1961 | C3: Graduation | D3: Single | E3: 57091 | F3: 0 | G3: 0 | H3: 41805 | I3: 0 | J3: 464 | K3: 5 | L3: 64 | M3: 7 | N3: 0 | O3: 37 | P3: 1 | Q3: 7 | R3: 3 | S3: 7 | T3: 5 | U3: 0 | V3: 0 | W3: 0 | X3: 0 | Y3: 1 | Z3: 1 | AA3: 0 | AB3: Canada | AC3: =YEAR(TODAY()) - B3 -> 65 | AD3: =SUM(J3:O3) -> 577 | AE3: =SUM(P3:T3) -> 23
A4: 10476 | B4: 1958 | C4: Graduation | D4: Married | E4: 67267 | F4: 0 | G4: 1 | H4: 41772 | I4: 0 | J4: 134 | K4: 11 | L4: 59 | M4: 15 | N4: 2 | O4: 30 | P4: 1 | Q4: 3 | R4: 2 | S4: 5 | T4: 2 | U4: 0 | V4: 0 | W4: 0 | X4: 0 | Y4: 0 | Z4: 0 | AA4: 0 | AB4: USA | AC4: =YEAR(TODAY()) - B4 -> 68 | AD4: =SUM(J4:O4) -> 251 | AE4: =SUM(P4:T4) -> 13
A5: 1386 | B5: 1967 | C5: Graduation | D5: Together | E5: 32474 | F5: 1 | G5: 1 | H5: 41770 | I5: 0 | J5: 10 | K5: 0 | L5: 1 | M5: 0 | N5: 0 | O5: 0 | P5: 1 | Q5: 1 | R5: 0 | S5: 2 | T5: 7 | U5: 0 | V5: 0 | W5: 0 | X5: 0 | Y5: 0 | Z5: 0 | AA5: 0 | AB5: Australia | AC5: =YEAR(TODAY()) - B5 -> 59 | AD5: =SUM(J5:O5) -> 11 | AE5: =SUM(P5:T5) -> 11
A6: 5371 | B6: 1989 | C6: Graduation | D6: Single | E6: 21474 | F6: 1 | G6: 0 | H6: 41737 | I6: 0 | J6: 6 | K6: 16 | L6: 24 | M6: 11 | N6: 0 | O6: 34 | P6: 2 | Q6: 3 | R6: 1 | S6: 2 | T6: 7 | U6: 1 | V6: 0 | W6: 0 | X6: 0 | Y6: 0 | Z6: 1 | AA6: 0 | AB6: Spain | AC6: =YEAR(TODAY()) - B6 -> 37 | AD6: =SUM(J6:O6) -> 91 | AE6: =SUM(P6:T6) -> 15
A7: 7348 | B7: 1958 | C7: PhD | D7: Single | E7: 71691 | F7: 0 | G7: 0 | H7: 41715 | I7: 0 | J7: 336 | K7: 130 | L7: 411 | M7: 240 | N7: 32 | O7: 43 | P7: 1 | Q7: 4 | R7: 7 | S7: 5 | T7: 2 | U7: 0 | V7: 0 | W7: 0 | X7: 0 | Y7: 0 | Z7: 1 | AA7: 0 | AB7: Spain | AC7: =YEAR(TODAY()) - B7 -> 68 | AD7: =SUM(J7:O7) -> 1192 | AE7: =SUM(P7:T7) -> 19
A8: 4073 | B8: 1954 | C8: 2n Cycle | D8: Married | E8: 63564 | F8: 0 | G8: 0 | H8: 41668 | I8: 0 | J8: 769 | K8: 80 | L8: 252 | M8: 15 | N8: 34 | O8: 65 | P8: 1 | Q8: 10 | R8: 10 | S8: 7 | T8: 6 | U8: 1 | V8: 0 | W8: 0 | X8: 0 | Y8: 0 | Z8: 1 | AA8: 0 | AB8: Germany | AC8: =YEAR(TODAY()) - B8 -> 72 | AD8: =SUM(J8:O8) -> 1215 | AE8: =SUM(P8:T8) -> 34
A9: 1991 | B9: 1967 | C9: Graduation | D9: Together | E9: 44931 | F9: 0 | G9: 1 | H9: 41657 | I9: 0 | J9: 78 | K9: 0 | L9: 11 | M9: 0 | N9: 0 | O9: 7 | P9: 1 | Q9: 2 | R9: 1 | S9: 3 | T9: 5 | U9: 0 | V9: 0 | W9: 0 | X9: 0 | Y9: 0 | Z9: 0 | AA9: 0 | AB9: Spain | AC9: =YEAR(TODAY()) - B9 -> 59 | AD9: =SUM(J9:O9) -> 96 | AE9: =SUM(P9:T9) -> 12
A10: 4047 | B10: 1954 | C10: PhD | D10: Married | E10: 65324 | F10: 0 | G10: 1 | H10: 41650 | I10: 0 | J10: 384 | K10: 0 | L10: 102 | M10: 21 | N10: 32 | O10: 5 | P10: 3 | Q10: 6 | R10: 2 | S10: 9 | T10: 4 | U10: 0 | V10: 0 | W10: 0 | X10: 0 | Y10: 0 | Z10: 0 | AA10: 0 | AB10: USA | AC10: =YEAR(TODAY()) - B10 -> 72 | AD10: =SUM(J10:O10) -> 544 | AE10: =SUM(P10:T10) -> 24
A11: 9477 | B11: 1954 | C11: PhD | D11: Married | E11: 65324 | F11: 0 | G11: 1 | H11: 41650 | I11: 0 | J11: 384 | K11: 0 | L11: 102 | M11: 21 | N11: 32 | O11: 5 | P11: 3 | Q11: 6 | R11: 2 | S11: 9 | T11: 4 | U11: 0 | V11: 0 | W11: 0 | X11: 0 | Y11: 0 | Z11: 0 | AA11: 0 | AB11: India | AC11: =YEAR(TODAY()) - B11 -> 72 | AD11: =SUM(J11:O11) -> 544 | AE11: =SUM(P11:T11) -> 24
A12: 2079 | B12: 1947 | C12: 2n Cycle | D12: Married | E12: 81044 | F12: 0 | G12: 0 | H12: 41635 | I12: 0 | J12: 450 | K12: 26 | L12: 535 | M12: 73 | N12: 98 | O12: 26 | P12: 1 | Q12: 5 | R12: 6 | S12: 10 | T12: 1 | U12: 0 | V12: 0 | W12: 0 | X12: 0 | Y12: 0 | Z12: 0 | AA12: 0 | AB12: USA | AC12: =YEAR(TODAY()) - B12 -> 79 | AD12: =SUM(J12:O12) -> 1208 | AE12: =SUM(P12:T12) -> 23
A13: 5642 | B13: 1979 | C13: Master | D13: Together | E13: 62499 | F13: 1 | G13: 0 | H13: 41617 | I13: 0 | J13: 140 | K13: 4 | L13: 61 | M13: 0 | N13: 13 | O13: 4 | P13: 2 | Q13: 3 | R13: 1 | S13: 6 | T13: 4 | U13: 0 | V13: 0 | W13: 0 | X13: 0 | Y13: 0 | Z13: 0 | AA13: 0 | AB13: Spain | AC13: =YEAR(TODAY()) - B13 -> 47 | AD13: =SUM(J13:O13) -> 222 | AE13: =SUM(P13:T13) -> 16
... A135: 8619 | B135: 1957 | C135: Graduation | D135: Together | E135: 21994 | F135: 0 | G135: 1 | H135: 41267 | I135: 4 | J135: 9 | K135: 0 | L135: 6 | M135: 3 | N135: 1 | O135: 3 | P135: 1 | Q135: 0 | R135: 0 | S135: 3 | T135: 5 | U135: 0 | V135: 0 | W135: 0 | X135: 0 | Y135: 0 | Z135: 0 | AA135: 0 | AB135: Spain | AC135: =YEAR(TODAY()) - B135 -> 69 | AD135: =SUM(J135:O135) -> 22 | AE135: =SUM(P135:T135) -> 9
A136: 8996 | B136: 1957 | C136: PhD | D136: Married | F136: 2 | G136: 1 | H136: 41232 | I136: 4 | J136: 230 | K136: 42 | L136: 192 | M136: 49 | N136: 37 | O136: 53 | P136: 12 | Q136: 7 | R136: 2 | S136: 8 | T136: 9 | U136: 0 | V136: 0 | W136: 0 | X136: 0 | Y136: 0 | Z136: 0 | AA136: 0 | AB136: Germany | AC136: =YEAR(TODAY()) - B136 -> 69 | AD136: =SUM(J136:O136) -> 603 | AE136: =SUM(P136:T136) -> 38
A137: 7233 | B137: 1972 | C137: Graduation | D137: Married | E137: 69209 | F137: 0 | G137: 0 | H137: 41169 | I137: 4 | J137: 496 | K137: 32 | L137: 849 | M137: 229 | N137: 48 | O137: 128 | P137: 2 | Q137: 5 | R137: 3 | S137: 6 | T137: 4 | U137: 0 | V137: 0 | W137: 0 | X137: 1 | Y137: 0 | Z137: 0 | AA137: 0 | AB137: Canada | AC137: =YEAR(TODAY()) - B137 -> 54 | AD137: =SUM(J137:O137) -> 1782 | AE137: =SUM(P137:T137) -> 20
A138: 6678 | B138: 1989 | C138: Graduation | D138: Together | E138: 31928 | F138: 1 | G138: 0 | H138: 41726 | I138: 5 | J138: 33 | K138: 4 | L138: 24 | M138: 4 | N138: 2 | O138: 5 | P138: 2 | Q138: 3 | R138: 0 | S138: 4 | T138: 7 | U138: 0 | V138: 0 | W138: 0 | X138: 0 | Y138: 0 | Z138: 0 | AA138: 0 | AB138: India | AC138: =YEAR(TODAY()) - B138 -> 37 | AD138: =SUM(J138:O138) -> 72 | AE138: =SUM(P138:T138) -> 16
A139: 830 | B139: 1987 | C139: PhD | D139: Single | E139: 74004 | F139: 0 | G139: 0 | H139: 41694 | I139: 5 | J139: 784 | K139: 48 | L139: 560 | M139: 42 | N139: 176 | O139: 48 | P139: 1 | Q139: 4 | R139: 6 | S139: 4 | T139: 3 | U139: 0 | V139: 0 | W139: 1 | X139: 1 | Y139: 0 | Z139: 1 | AA139: 0 | AB139: India | AC139: =YEAR(TODAY()) - B139 -> 39 | AD139: =SUM(J139:O139) -> 1658 | AE139: =SUM(P139:T139) -> 18
A140: 6365 | B140: 1987 | C140: 2n Cycle | D140: Married | E140: 30390 | F140: 0 | G140: 0 | H140: 41519 | I140: 5 | J140: 10 | K140: 12 | L140: 12 | M140: 25 | N140: 1 | O140: 20 | P140: 1 | Q140: 2 | R140: 0 | S140: 3 | T140: 6 | U140: 0 | V140: 0 | W140: 0 | X140: 0 | Y140: 0 | Z140: 0 | AA140: 0 | AB140: India | AC140: =YEAR(TODAY()) - B140 -> 39 | AD140: =SUM(J140:O140) -> 80 | AE140: =SUM(P140:T140) -> 12
A141: 6770 | B141: 1985 | C141: Graduation | D141: Married | E141: 21355 | F141: 1 | G141: 0 | H141: 41506 | I141: 5 | J141: 5 | K141: 13 | L141: 14 | M141: 0 | N141: 5 | O141: 31 | P141: 2 | Q141: 2 | R141: 1 | S141: 2 | T141: 6 | U141: 1 | V141: 0 | W141: 0 | X141: 0 | Y141: 0 | Z141: 1 | AA141: 0 | AB141: USA | AC141: =YEAR(TODAY()) - B141 -> 41 | AD141: =SUM(J141:O141) -> 68 | AE141: =SUM(P141:T141) -> 13
A142: 2261 | B142: 1969 | C142: Graduation | D142: Married | E142: 26304 | F142: 1 | G142: 0 | H142: 41448 | I142: 5 | J142: 4 | K142: 1 | L142: 5 | M142: 2 | N142: 0 | O142: 4 | P142: 1 | Q142: 1 | R142: 0 | S142: 2 | T142: 7 | U142: 0 | V142: 0 | W142: 0 | X142: 0 | Y142: 0 | Z142: 0 | AA142: 0 | AB142: Germany | AC142: =YEAR(TODAY()) - B142 -> 57 | AD142: =SUM(J142:O142) -> 16 | AE142: =SUM(P142:T142) -> 11
A143: 1031 | B143: 1989 | C143: 2n Cycle | D143: Married | E143: 85710 | F143: 0 | G143: 0 | H143: 41399 | I143: 5 | J143: 600 | K143: 20 | L143: 350 | M143: 29 | N143: 30 | O143: 33 | P143: 1 | Q143: 6 | R143: 9 | S143: 10 | T143: 2 | U143: 0 | V143: 0 | W143: 1 | X143: 0 | Y143: 0 | Z143: 0 | AA143: 0 | AB143: India | AC143: =YEAR(TODAY()) - B143 -> 37 | AD143: =SUM(J143:O143) -> 1062 | AE143: =SUM(P143:T143) -> 28
A144: 10089 | B144: 1974 | C144: Graduation | D144: Divorced | E144: 102692 | F144: 0 | G144: 0 | H144: 41369 | I144: 5 | J144: 168 | K144: 148 | L144: 444 | M144: 32 | N144: 172 | O144: 148 | P144: 1 | Q144: 6 | R144: 9 | S144: 13 | T144: 2 | U144: 0 | V144: 1 | W144: 1 | X144: 1 | Y144: 1 | Z144: 1 | AA144: 0 | AB144: Saudi Arabia | AC144: =YEAR(TODAY()) - B144 -> 52 | AD144: =SUM(J144:O144) -> 1112 | AE144: =SUM(P144:T144) -> 31
A145: 9256 | B145: 1971 | C145: Graduation | D145: Single | E145: 58350 | F145: 0 | G145: 1 | H145: 41278 | I145: 5 | J145: 493 | K145: 26 | L145: 206 | M145: 116 | N145: 80 | O145: 80 | P145: 4 | Q145: 8 | R145: 3 | S145: 12 | T145: 6 | U145: 0 | V145: 0 | W145: 0 | X145: 0 | Y145: 0 | Z145: 0 | AA145: 0 | AB145: Spain | AC145: =YEAR(TODAY()) - B145 -> 55 | AD145: =SUM(J145:O145) -> 1001 | AE145: =SUM(P145:T145) -> 33
A146: 10641 | B146: 1978 | C146: Graduation | D146: Single | E146: 7500 | F146: 1 | G146: 1 | H146: 41270 | I146: 5 | J146: 6 | K146: 5 | L146: 4 | M146: 13 | N146: 4 | O146: 25 | P146: 4 | Q146: 2 | R146: 1 | S146: 3 | T146: 6 | U146: 0 | V146: 0 | W146: 0 | X146: 0 | Y146: 0 | Z146: 0 | AA146: 0 | AB146: Spain | AC146: =YEAR(TODAY()) - B146 -> 48 | AD146: =SUM(J146:O146) -> 57 | AE146: =SUM(P146:T146) -> 16
A147: 624 | B147: 1984 | C147: Master | D147: Single | E147: 18890 | F147: 0 | G147: 0 | H147: 41223 | I147: 5 | J147: 6 | K147: 4 | L147: 1 | M147: 7 | N147: 2 | O147: 15 | P147: 1 | Q147: 0 | R147: 1 | S147: 2 | T147: 6 | U147: 1 | V147: 0 | W147: 0 | X147: 0 | Y147: 0 | Z147: 1 | AA147: 0 | AB147: Saudi Arabia | AC147: =YEAR(TODAY()) - B147 -> 42 | AD147: =SUM(J147:O147) -> 35 | AE147: =SUM(P147:T147) -> 10
A148: 4211 | B148: 1986 | C148: Basic | D148: Married | E148: 20425 | F148: 1 | G148: 0 | H148: 41211 | I148: 5 | J148: 4 | K148: 12 | L148: 5 | M148: 3 | N148: 16 | O148: 17 | P148: 2 | Q148: 2 | R148: 0 | S148: 3 | T148: 7 | U148: 0 | V148: 0 | W148: 0 | X148: 0 | Y148: 0 | Z148: 0 | AA148: 0 | AB148: Canada | AC148: =YEAR(TODAY()) - B148 -> 40 | AD148: =SUM(J148:O148) -> 57 | AE148: =SUM(P148:T148) -> 14
... A263: 11191 | B263: 1986 | C263: Graduation | D263: Divorced | E263: 41411 | F263: 0 | G263: 0 | H263: 41615 | I263: 11 | J263: 37 | K263: 32 | L263: 38 | M263: 11 | N263: 3 | O263: 18 | P263: 1 | Q263: 2 | R263: 1 | S263: 4 | T263: 6 | U263: 0 | V263: 0 | W263: 0 | X263: 0 | Y263: 0 | Z263: 0 | AA263: 0 | AB263: Spain | AC263: =YEAR(TODAY()) - B263 -> 40 | AD263: =SUM(J263:O263) -> 139 | AE263: =SUM(P263:T263) -> 14
A264: 1994 | B264: 1983 | C264: Graduation | D264: Married | F264: 1 | G264: 0 | H264: 41593 | I264: 11 | J264: 5 | K264: 5 | L264: 6 | M264: 0 | N264: 2 | O264: 1 | P264: 1 | Q264: 1 | R264: 0 | S264: 2 | T264: 7 | U264: 0 | V264: 0 | W264: 0 | X264: 0 | Y264: 0 | Z264: 0 | AA264: 0 | AB264: USA | AC264: =YEAR(TODAY()) - B264 -> 43 | AD264: =SUM(J264:O264) -> 19 | AE264: =SUM(P264:T264) -> 11
A265: 2552 | B265: 1955 | C265: PhD | D265: Single | E265: 55521 | F265: 1 | G265: 2 | H265: 41569 | I265: 11 | J265: 416 | K265: 0 | L265: 26 | M265: 0 | N265: 0 | O265: 4 | P265: 9 | Q265: 6 | R265: 3 | S265: 6 | T265: 7 | U265: 0 | V265: 1 | W265: 0 | X265: 0 | Y265: 0 | Z265: 1 | AA265: 0 | AB265: Spain | AC265: =YEAR(TODAY()) - B265 -> 71 | AD265: =SUM(J265:O265) -> 446 | AE265: =SUM(P265:T265) -> 31
A266: 6720 | B266: 1968 | C266: Master | D266: Together | E266: 43795 | F266: 0 | G266: 1 | H266: 41563 | I266: 11 | J266: 314 | K266: 11 | L266: 53 | M266: 4 | N266: 3 | O266: 107 | P266: 3 | Q266: 7 | R266: 3 | S266: 4 | T266: 7 | U266: 0 | V266: 1 | W266: 0 | X266: 0 | Y266: 0 | Z266: 1 | AA266: 0 | AB266: Spain | AC266: =YEAR(TODAY()) - B266 -> 58 | AD266: =SUM(J266:O266) -> 492 | AE266: =SUM(P266:T266) -> 24
A267: 4557 | B267: 1970 | C267: Graduation | D267: Together | E267: 22070 | F267: 1 | G267: 0 | H267: 41551 | I267: 11 | J267: 10 | K267: 7 | L267: 19 | M267: 8 | N267: 2 | O267: 21 | P267: 2 | Q267: 2 | R267: 2 | S267: 2 | T267: 6 | U267: 0 | V267: 0 | W267: 0 | X267: 0 | Y267: 0 | Z267: 0 | AA267: 0 | AB267: Saudi Arabia | AC267: =YEAR(TODAY()) - B267 -> 56 | AD267: =SUM(J267:O267) -> 67 | AE267: =SUM(P267:T267) -> 14
A268: 1183 | B268: 1949 | C268: Master | D268: Married | E268: 36408 | F268: 1 | G268: 1 | H268: 41538 | I268: 11 | J268: 9 | K268: 1 | L268: 4 | M268: 3 | N268: 2 | O268: 3 | P268: 1 | Q268: 1 | R268: 0 | S268: 2 | T268: 6 | U268: 0 | V268: 0 | W268: 0 | X268: 0 | Y268: 0 | Z268: 0 | AA268: 0 | AB268: Germany | AC268: =YEAR(TODAY()) - B268 -> 77 | AD268: =SUM(J268:O268) -> 22 | AE268: =SUM(P268:T268) -> 10
A269: 4186 | B269: 1950 | C269: Graduation | D269: Together | E269: 34026 | F269: 1 | G269: 1 | H269: 41491 | I269: 11 | J269: 18 | K269: 6 | L269: 15 | M269: 12 | N269: 8 | O269: 17 | P269: 3 | Q269: 2 | R269: 1 | S269: 3 | T269: 5 | U269: 0 | V269: 0 | W269: 0 | X269: 0 | Y269: 0 | Z269: 0 | AA269: 0 | AB269: Canada | AC269: =YEAR(TODAY()) - B269 -> 76 | AD269: =SUM(J269:O269) -> 76 | AE269: =SUM(P269:T269) -> 14
A270: 1419 | B270: 1950 | C270: Graduation | D270: Together | E270: 34026 | F270: 1 | G270: 1 | H270: 41491 | I270: 11 | J270: 18 | K270: 6 | L270: 15 | M270: 12 | N270: 8 | O270: 17 | P270: 3 | Q270: 2 | R270: 1 | S270: 3 | T270: 5 | U270: 0 | V270: 0 | W270: 0 | X270: 0 | Y270: 0 | Z270: 0 | AA270: 0 | AB270: Spain | AC270: =YEAR(TODAY()) - B270 -> 76 | AD270: =SUM(J270:O270) -> 76 | AE270: =SUM(P270:T270) -> 14
A271: 967 | B271: 1976 | C271: Graduation | D271: Married | E271: 46049 | F271: 1 | G271: 1 | H271: 41476 | I271: 11 | J271: 342 | K271: 9 | L271: 112 | M271: 19 | N271: 14 | O271: 19 | P271: 10 | Q271: 5 | R271: 2 | S271: 9 | T271: 7 | U271: 0 | V271: 0 | W271: 0 | X271: 0 | Y271: 0 | Z271: 1 | AA271: 0 | AB271: Spain | AC271: =YEAR(TODAY()) - B271 -> 50 | AD271: =SUM(J271:O271) -> 515 | AE271: =SUM(P271:T271) -> 33
A272: 1048 | B272: 1972 | C272: Master | D272: Married | E272: 35641 | F272: 1 | G272: 0 | H272: 41469 | I272: 11 | J272: 63 | K272: 3 | L272: 67 | M272: 8 | N272: 9 | O272: 28 | P272: 2 | Q272: 3 | R272: 1 | S272: 4 | T272: 7 | U272: 0 | V272: 0 | W272: 0 | X272: 0 | Y272: 0 | Z272: 1 | AA272: 0 | AB272: Saudi Arabia | AC272: =YEAR(TODAY()) - B272 -> 54 | AD272: =SUM(J272:O272) -> 178 | AE272: =SUM(P272:T272) -> 17
A273: 9262 | B273: 1984 | C273: 2n Cycle | D273: Together | E273: 32414 | F273: 0 | G273: 0 | H273: 41459 | I273: 11 | J273: 20 | K273: 6 | L273: 5 | M273: 0 | N273: 9 | O273: 12 | P273: 1 | Q273: 1 | R273: 0 | S273: 3 | T273: 7 | U273: 1 | V273: 0 | W273: 0 | X273: 0 | Y273: 0 | Z273: 0 | AA273: 0 | AB273: Saudi Arabia | AC273: =YEAR(TODAY()) - B273 -> 42 | AD273: =SUM(J273:O273) -> 52 | AE273: =SUM(P273:T273) -> 12
A274: 3427 | B274: 1955 | C274: PhD | D274: Married | E274: 59821 | F274: 0 | G274: 1 | H274: 41376 | I274: 11 | J274: 629 | K274: 0 | L274: 70 | M274: 0 | N274: 0 | O274: 35 | P274: 6 | Q274: 11 | R274: 2 | S274: 7 | T274: 8 | U274: 0 | V274: 0 | W274: 0 | X274: 0 | Y274: 0 | Z274: 0 | AA274: 0 | AB274: Saudi Arabia | AC274: =YEAR(TODAY()) - B274 -> 71 | AD274: =SUM(J274:O274) -> 734 | AE274: =SUM(P274:T274) -> 34
A275: 5892 | B275: 1980 | C275: Graduation | D275: Married | E275: 34968 | F275: 1 | G275: 0 | H275: 41374 | I275: 11 | J275: 158 | K275: 6 | L275: 45 | M275: 8 | N275: 2 | O275: 2 | P275: 7 | Q275: 3 | R275: 2 | S275: 5 | T275: 7 | U275: 0 | V275: 0 | W275: 0 | X275: 0 | Y275: 0 | Z275: 0 | AA275: 0 | AB275: Saudi Arabia | AC275: =YEAR(TODAY()) - B275 -> 46 | AD275: =SUM(J275:O275) -> 221 | AE275: =SUM(P275:T275) -> 24
...

Sheet marketing_data (2)
A1: ID | B1: Year_Birth | C1: Education | D1: Marital_Status | E1: Income | F1: Kidhome | G1: Teenhome | H1: Dt_Customer | I1: Recency | J1: MntWines | K1: MntFruits | L1: MntMeatProducts | M1: MntFishProducts | N1: MntSweetProducts | O1: MntGoldProds | P1: NumDealsPurchases | Q1: NumWebPurchases | R1: NumCatalogPurchases | S1: NumStorePurchases | T1: NumWebVisitsMonth | U1: AcceptedCmp3 | V1: AcceptedCmp4 | W1: AcceptedCmp5 | X1: AcceptedCmp1 | Y1: AcceptedCmp2 | Z1: Response | AA1: Complain | AB1: Country | AC1: Age | AD1: Total Spend | AE1: Total Purchases | AF1: Income Band | AG1: Age Band | AH1: Recency Band | AI1: Spending Band | AJ1: Total Campaigns Accepted | AK1: Total Accepted Band
A2: 1826 | B2: 1970 | C2: Graduation | D2: Divorced | E2: 84835 | F2: 0 | G2: 0 | H2: 41806 | I2: 0 | J2: 189 | K2: 104 | L2: 379 | M2: 111 | N2: 189 | O2: 218 | P2: 1 | Q2: 4 | R2: 4 | S2: 6 | T2: 1 | U2: 0 | V2: 0 | W2: 0 | X2: 0 | Y2: 0 | Z2: 1 | AA2: 0 | AB2: Spain | AC2: =YEAR(TODAY()) - B2 -> 56 | AD2: =SUM(J2:O2) -> 1190 | AE2: =SUM(P2:T2) -> 16 | AF2: =IF(Table2[[#This Row],[ Income ]]<=30000, "Low Income",IF(Table2[[#This Row],[ Income ]]<=60000,"Middle Income",IF(Table2[[#This Row],[ Income ]]<=90000,"High Income","Premium"))) -> High Income | AG2: =IF(Table2[[#This Row],[Age]]<30,"Young Adults", IF(Table2[[#This Row],[Age]]<45,"Adults",IF(Table2[[#This Row],[Age]]<60,"Middle Aged", "Senior"))) -> Middle Aged | AH2: =IF(Table2[[#This Row],[Recency]]<31,"Active",IF(Table2[[#This Row],[Recency]]<61, "Warm","At Risk")) -> Active | AI2: =IF(Table2[[#This Row],[Total Spend]]<70,"Low Value", IF(Table2[[#This Row],[Total Spend]]<370,"Medium Value",IF(Table2[[#This Row],[Total Spend]]<1047,"High Value","VIP"))) -> VIP | AJ2: =SUM(Table2[[#This Row],[AcceptedCmp3]:[Response]]) -> 1 | AK2: =IF(Table2[[#This Row],[Total Campaigns Accepted]]=0,"Never Responded", IF(Table2[[#This Row],[Total Campaigns Accepted]]<3,"Occasional Responders","Frequent Responders")) -> Occasional Responders
A3: 1 | B3: 1961 | C3: Graduation | D3: Single | E3: 57091 | F3: 0 | G3: 0 | H3: 41805 | I3: 0 | J3: 464 | K3: 5 | L3: 64 | M3: 7 | N3: 0 | O3: 37 | P3: 1 | Q3: 7 | R3: 3 | S3: 7 | T3: 5 | U3: 0 | V3: 0 | W3: 0 | X3: 0 | Y3: 1 | Z3: 1 | AA3: 0 | AB3: Canada | AC3: =YEAR(TODAY()) - B3 -> 65 | AD3: =SUM(J3:O3) -> 577 | AE3: =SUM(P3:T3) -> 23 | AF3: =IF(Table2[[#This Row],[ Income ]]<=30000, "Low Income",IF(Table2[[#This Row],[ Income ]]<=60000,"Middle Income",IF(Table2[[#This Row],[ Income ]]<=90000,"High Income","Premium"))) -> Middle Income | AG3: =IF(Table2[[#This Row],[Age]]<30,"Young Adults", IF(Table2[[#This Row],[Age]]<45,"Adults",IF(Table2[[#This Row],[Age]]<60,"Middle Aged", "Senior"))) -> Senior | AH3: =IF(Table2[[#This Row],[Recency]]<31,"Active",IF(Table2[[#This Row],[Recency]]<61, "Warm","At Risk")) -> Active | AI3: =IF(Table2[[#This Row],[Total Spend]]<70,"Low Value", IF(Table2[[#This Row],[Total Spend]]<370,"Medium Value",IF(Table2[[#This Row],[Total Spend]]<1047,"High Value","VIP"))) -> High Value | AJ3: =SUM(Table2[[#This Row],[AcceptedCmp3]:[Response]]) -> 2 | AK3: =IF(Table2[[#This Row],[Total Campaigns Accepted]]=0,"Never Responded", IF(Table2[[#This Row],[Total Campaigns Accepted]]<3,"Occasional Responders","Frequent Responders")) -> Occasional Responders
A4: 10476 | B4: 1958 | C4: Graduation | D4: Married | E4: 67267 | F4: 0 | G4: 1 | H4: 41772 | I4: 0 | J4: 134 | K4: 11 | L4: 59 | M4: 15 | N4: 2 | O4: 30 | P4: 1 | Q4: 3 | R4: 2 | S4: 5 | T4: 2 | U4: 0 | V4: 0 | W4: 0 | X4: 0 | Y4: 0 | Z4: 0 | AA4: 0 | AB4: USA | AC4: =YEAR(TODAY()) - B4 -> 68 | AD4: =SUM(J4:O4) -> 251 | AE4: =SUM(P4:T4) -> 13 | AF4: =IF(Table2[[#This Row],[ Income ]]<=30000, "Low Income",IF(Table2[[#This Row],[ Income ]]<=60000,"Middle Income",IF(Table2[[#This Row],[ Income ]]<=90000,"High Income","Premium"))) -> High Income | AG4: =IF(Table2[[#This Row],[Age]]<30,"Young Adults", IF(Table2[[#This Row],[Age]]<45,"Adults",IF(Table2[[#This Row],[Age]]<60,"Middle Aged", "Senior"))) -> Senior | AH4: =IF(Table2[[#This Row],[Recency]]<31,"Active",IF(Table2[[#This Row],[Recency]]<61, "Warm","At Risk")) -> Active | AI4: =IF(Table2[[#This Row],[Total Spend]]<70,"Low Value", IF(Table2[[#This Row],[Total Spend]]<370,"Medium Value",IF(Table2[[#This Row],[Total Spend]]<1047,"High Value","VIP"))) -> Medium Value | AJ4: =SUM(Table2[[#This Row],[AcceptedCmp3]:[Response]]) -> 0 | AK4: =IF(Table2[[#This Row],[Total Campaigns Accepted]]=0,"Never Responded", IF(Table2[[#This Row],[Total Campaigns Accepted]]<3,"Occasional Responders","Frequent Responders")) -> Never Responded
A5: 1386 | B5: 1967 | C5: Graduation | D5: Together | E5: 32474 | F5: 1 | G5: 1 | H5: 41770 | I5: 0 | J5: 10 | K5: 0 | L5: 1 | M5: 0 | N5: 0 | O5: 0 | P5: 1 | Q5: 1 | R5: 0 | S5: 2 | T5: 7 | U5: 0 | V5: 0 | W5: 0 | X5: 0 | Y5: 0 | Z5: 0 | AA5: 0 | AB5: Australia | AC5: =YEAR(TODAY()) - B5 -> 59 | AD5: =SUM(J5:O5) -> 11 | AE5: =SUM(P5:T5) -> 11 | AF5: =IF(Table2[[#This Row],[ Income ]]<=30000, "Low Income",IF(Table2[[#This Row],[ Income ]]<=60000,"Middle Income",IF(Table2[[#This Row],[ Income ]]<=90000,"High Income","Premium"))) -> Middle Income | AG5: =IF(Table2[[#This Row],[Age]]<30,"Young Adults", IF(Table2[[#This Row],[Age]]<45,"Adults",IF(Table2[[#This Row],[Age]]<60,"Middle Aged", "Senior"))) -> Middle Aged | AH5: =IF(Table2[[#This Row],[Recency]]<31,"Active",IF(Table2[[#This Row],[Recency]]<61, "Warm","At Risk")) -> Active | AI5: =IF(Table2[[#This Row],[Total Spend]]<70,"Low Value", IF(Table2[[#This Row],[Total Spend]]<370,"Medium Value",IF(Table2[[#This Row],[Total Spend]]<1047,"High Value","VIP"))) -> Low Value | AJ5: =SUM(Table2[[#This Row],[AcceptedCmp3]:[Response]]) -> 0 | AK5: =IF(Table2[[#This Row],[Total Campaigns Accepted]]=0,"Never Responded", IF(Table2[[#This Row],[Total Campaigns Accepted]]<3,"Occasional Responders","Frequent Responders")) -> Never Responded
A6: 5371 | B6: 1989 | C6: Graduation | D6: Single | E6: 21474 | F6: 1 | G6: 0 | H6: 41737 | I6: 0 | J6: 6 | K6: 16 | L6: 24 | M6: 11 | N6: 0 | O6: 34 | P6: 2 | Q6: 3 | R6: 1 | S6: 2 | T6: 7 | U6: 1 | V6: 0 | W6: 0 | X6: 0 | Y6: 0 | Z6: 1 | AA6: 0 | AB6: Spain | AC6: =YEAR(TODAY()) - B6 -> 37 | AD6: =SUM(J6:O6) -> 91 | AE6: =SUM(P6:T6) -> 15 | AF6: =IF(Table2[[#This Row],[ Income ]]<=30000, "Low Income",IF(Table2[[#This Row],[ Income ]]<=60000,"Middle Income",IF(Table2[[#This Row],[ Income ]]<=90000,"High Income","Premium"))) -> Low Income | AG6: =IF(Table2[[#This Row],[Age]]<30,"Young Adults", IF(Table2[[#This Row],[Age]]<45,"Adults",IF(Table2[[#This Row],[Age]]<60,"Middle Aged", "Senior"))) -> Adults | AH6: =IF(Table2[[#This Row],[Recency]]<31,"Active",IF(Table2[[#This Row],[Recency]]<61, "Warm","At Risk")) -> Active | AI6: =IF(Table2[[#This Row],[Total Spend]]<70,"Low Value", IF(Table2[[#This Row],[Total Spend]]<370,"Medium Value",IF(Table2[[#This Row],[Total Spend]]<1047,"High Value","VIP"))) -> Medium Value | AJ6: =SUM(Table2[[#This Row],[AcceptedCmp3]:[Response]]) -> 2 | AK6: =IF(Table2[[#This Row],[Total Campaigns Accepted]]=0,"Never Responded", IF(Table2[[#This Row],[Total Campaigns Accepted]]<3,"Occasional Responders","Frequent Responders")) -> Occasional Responders
A7: 7348 | B7: 1958 | C7: PhD | D7: Single | E7: 71691 | F7: 0 | G7: 0 | H7: 41715 | I7: 0 | J7: 336 | K7: 130 | L7: 411 | M7: 240 | N7: 32 | O7: 43 | P7: 1 | Q7: 4 | R7: 7 | S7: 5 | T7: 2 | U7: 0 | V7: 0 | W7: 0 | X7: 0 | Y7: 0 | Z7: 1 | AA7: 0 | AB7: Spain | AC7: =YEAR(TODAY()) - B7 -> 68 | AD7: =SUM(J7:O7) -> 1192 | AE7: =SUM(P7:T7) -> 19 | AF7: =IF(Table2[[#This Row],[ Income ]]<=30000, "Low Income",IF(Table2[[#This Row],[ Income ]]<=60000,"Middle Income",IF(Table2[[#This Row],[ Income ]]<=90000,"High Income","Premium"))) -> High Income | AG7: =IF(Table2[[#This Row],[Age]]<30,"Young Adults", IF(Table2[[#This Row],[Age]]<45,"Adults",IF(Table2[[#This Row],[Age]]<60,"Middle Aged", "Senior"))) -> Senior | AH7: =IF(Table2[[#This Row],[Recency]]<31,"Active",IF(Table2[[#This Row],[Recency]]<61, "Warm","At Risk")) -> Active | AI7: =IF(Table2[[#This Row],[Total Spend]]<70,"Low Value", IF(Table2[[#This Row],[Total Spend]]<370,"Medium Value",IF(Table2[[#This Row],[Total Spend]]<1047,"High Value","VIP"))) -> VIP | AJ7: =SUM(Table2[[#This Row],[AcceptedCmp3]:[Response]]) -> 1 | AK7: =IF(Table2[[#This Row],[Total Campaigns Accepted]]=0,"Never Responded", IF(Table2[[#This Row],[Total Campaigns Accepted]]<3,"Occasional Responders","Frequent Responders")) -> Occasional Responders
A8: 4073 | B8: 1954 | C8: 2n Cycle | D8: Married | E8: 63564 | F8: 0 | G8: 0 | H8: 41668 | I8: 0 | J8: 769 | K8: 80 | L8: 252 | M8: 15 | N8: 34 | O8: 65 | P8: 1 | Q8: 10 | R8: 10 | S8: 7 | T8: 6 | U8: 1 | V8: 0 | W8: 0 | X8: 0 | Y8: 0 | Z8: 1 | AA8: 0 | AB8: Germany | AC8: =YEAR(TODAY()) - B8 -> 72 | AD8: =SUM(J8:O8) -> 1215 | AE8: =SUM(P8:T8) -> 34 | AF8: =IF(Table2[[#This Row],[ Income ]]<=30000, "Low Income",IF(Table2[[#This Row],[ Income ]]<=60000,"Middle Income",IF(Table2[[#This Row],[ Income ]]<=90000,"High Income","Premium"))) -> High Income | AG8: =IF(Table2[[#This Row],[Age]]<30,"Young Adults", IF(Table2[[#This Row],[Age]]<45,"Adults",IF(Table2[[#This Row],[Age]]<60,"Middle Aged", "Senior"))) -> Senior | AH8: =IF(Table2[[#This Row],[Recency]]<31,"Active",IF(Table2[[#This Row],[Recency]]<61, "Warm","At Risk")) -> Active | AI8: =IF(Table2[[#This Row],[Total Spend]]<70,"Low Value", IF(Table2[[#This Row],[Total Spend]]<370,"Medium Value",IF(Table2[[#This Row],[Total Spend]]<1047,"High Value","VIP"))) -> VIP | AJ8: =SUM(Table2[[#This Row],[AcceptedCmp3]:[Response]]) -> 2 | AK8: =IF(Table2[[#This Row],[Total Campaigns Accepted]]=0,"Never Responded", IF(Table2[[#This Row],[Total Campaigns Accepted]]<3,"Occasional Responders","Frequent Responders")) -> Occasional Responders
A9: 1991 | B9: 1967 | C9: Graduation | D9: Together | E9: 44931 | F9: 0 | G9: 1 | H9: 41657 | I9: 0 | J9: 78 | K9: 0 | L9: 11 | M9: 0 | N9: 0 | O9: 7 | P9: 1 | Q9: 2 | R9: 1 | S9: 3 | T9: 5 | U9: 0 | V9: 0 | W9: 0 | X9: 0 | Y9: 0 | Z9: 0 | AA9: 0 | AB9: Spain | AC9: =YEAR(TODAY()) - B9 -> 59 | AD9: =SUM(J9:O9) -> 96 | AE9: =SUM(P9:T9) -> 12 | AF9: =IF(Table2[[#This Row],[ Income ]]<=30000, "Low Income",IF(Table2[[#This Row],[ Income ]]<=60000,"Middle Income",IF(Table2[[#This Row],[ Income ]]<=90000,"High Income","Premium"))) -> Middle Income | AG9: =IF(Table2[[#This Row],[Age]]<30,"Young Adults", IF(Table2[[#This Row],[Age]]<45,"Adults",IF(Table2[[#This Row],[Age]]<60,"Middle Aged", "Senior"))) -> Middle Aged | AH9: =IF(Table2[[#This Row],[Recency]]<31,"Active",IF(Table2[[#This Row],[Recency]]<61, "Warm","At Risk")) -> Active | AI9: =IF(Table2[[#This Row],[Total Spend]]<70,"Low Value", IF(Table2[[#This Row],[Total Spend]]<370,"Medium Value",IF(Table2[[#This Row],[Total Spend]]<1047,"High Value","VIP"))) -> Medium Value | AJ9: =SUM(Table2[[#This Row],[AcceptedCmp3]:[Response]]) -> 0 | AK9: =IF(Table2[[#This Row],[Total Campaigns Accepted]]=0,"Never Responded", IF(Table2[[#This Row],[Total Campaigns Accepted]]<3,"Occasional Responders","Frequent Responders")) -> Never Responded
A10: 4047 | B10: 1954 | C10: PhD | D10: Married | E10: 65324 | F10: 0 | G10: 1 | H10: 41650 | I10: 0 | J10: 384 | K10: 0 | L10: 102 | M10: 21 | N10: 32 | O10: 5 | P10: 3 | Q10: 6 | R10: 2 | S10: 9 | T10: 4 | U10: 0 | V10: 0 | W10: 0 | X10: 0 | Y10: 0 | Z10: 0 | AA10: 0 | AB10: USA | AC10: =YEAR(TODAY()) - B10 -> 72 | AD10: =SUM(J10:O10) -> 544 | AE10: =SUM(P10:T10) -> 24 | AF10: =IF(Table2[[#This Row],[ Income ]]<=30000, "Low Income",IF(Table2[[#This Row],[ Income ]]<=60000,"Middle Income",IF(Table2[[#This Row],[ Income ]]<=90000,"High Income","Premium"))) -> High Income | AG10: =IF(Table2[[#This Row],[Age]]<30,"Young Adults", IF(Table2[[#This Row],[Age]]<45,"Adults",IF(Table2[[#This Row],[Age]]<60,"Middle Aged", "Senior"))) -> Senior | AH10: =IF(Table2[[#This Row],[Recency]]<31,"Active",IF(Table2[[#This Row],[Recency]]<61, "Warm","At Risk")) -> Active | AI10: =IF(Table2[[#This Row],[Total Spend]]<70,"Low Value", IF(Table2[[#This Row],[Total Spend]]<370,"Medium Value",IF(Table2[[#This Row],[Total Spend]]<1047,"High Value","VIP"))) -> High Value | AJ10: =SUM(Table2[[#This Row],[AcceptedCmp3]:[Response]]) -> 0 | AK10: =IF(Table2[[#This Row],[Total Campaigns Accepted]]=0,"Never Responded", IF(Table2[[#This Row],[Total Campaigns Accepted]]<3,"Occasional Responders","Frequent Responders")) -> Never Responded
A11: 9477 | B11: 1954 | C11: PhD | D11: Married | E11: 65324 | F11: 0 | G11: 1 | H11: 41650 | I11: 0 | J11: 384 | K11: 0 | L11: 102 | M11: 21 | N11: 32 | O11: 5 | P11: 3 | Q11: 6 | R11: 2 | S11: 9 | T11: 4 | U11: 0 | V11: 0 | W11: 0 | X11: 0 | Y11: 0 | Z11: 0 | AA11: 0 | AB11: India | AC11: =YEAR(TODAY()) - B11 -> 72 | AD11: =SUM(J11:O11) -> 544 | AE11: =SUM(P11:T11) -> 24 | AF11: =IF(Table2[[#This Row],[ Income ]]<=30000, "Low Income",IF(Table2[[#This Row],[ Income ]]<=60000,"Middle Income",IF(Table2[[#This Row],[ Income ]]<=90000,"High Income","Premium"))) -> High Income | AG11: =IF(Table2[[#This Row],[Age]]<30,"Young Adults", IF(Table2[[#This Row],[Age]]<45,"Adults",IF(Table2[[#This Row],[Age]]<60,"Middle Aged", "Senior"))) -> Senior | AH11: =IF(Table2[[#This Row],[Recency]]<31,"Active",IF(Table2[[#This Row],[Recency]]<61, "Warm","At Risk")) -> Active | AI11: =IF(Table2[[#This Row],[Total Spend]]<70,"Low Value", IF(Table2[[#This Row],[Total Spend]]<370,"Medium Value",IF(Table2[[#This Row],[Total Spend]]<1047,"High Value","VIP"))) -> High Value | AJ11: =SUM(Table2[[#This Row],[AcceptedCmp3]:[Response]]) -> 0 | AK11: =IF(Table2[[#This Row],[Total Campaigns Accepted]]=0,"Never Responded", IF(Table2[[#This Row],[Total Campaigns Accepted]]<3,"Occasional Responders","Frequent Responders")) -> Never Responded
A12: 2079 | B12: 1947 | C12: 2n Cycle | D12: Married | E12: 81044 | F12: 0 | G12: 0 | H12: 41635 | I12: 0 | J12: 450 | K12: 26 | L12: 535 | M12: 73 | N12: 98 | O12: 26 | P12: 1 | Q12: 5 | R12: 6 | S12: 10 | T12: 1 | U12: 0 | V12: 0 | W12: 0 | X12: 0 | Y12: 0 | Z12: 0 | AA12: 0 | AB12: USA | AC12: =YEAR(TODAY()) - B12 -> 79 | AD12: =SUM(J12:O12) -> 1208 | AE12: =SUM(P12:T12) -> 23 | AF12: =IF(Table2[[#This Row],[ Income ]]<=30000, "Low Income",IF(Table2[[#This Row],[ Income ]]<=60000,"Middle Income",IF(Table2[[#This Row],[ Income ]]<=90000,"High Income","Premium"))) -> High Income | AG12: =IF(Table2[[#This Row],[Age]]<30,"Young Adults", IF(Table2[[#This Row],[Age]]<45,"Adults",IF(Table2[[#This Row],[Age]]<60,"Middle Aged", "Senior"))) -> Senior | AH12: =IF(Table2[[#This Row],[Recency]]<31,"Active",IF(Table2[[#This Row],[Recency]]<61, "Warm","At Risk")) -> Active | AI12: =IF(Table2[[#This Row],[Total Spend]]<70,"Low Value", IF(Table2[[#This Row],[Total Spend]]<370,"Medium Value",IF(Table2[[#This Row],[Total Spend]]<1047,"High Value","VIP"))) -> VIP | AJ12: =SUM(Table2[[#This Row],[AcceptedCmp3]:[Response]]) -> 0 | AK12: =IF(Table2[[#This Row],[Total Campaigns Accepted]]=0,"Never Responded", IF(Table2[[#This Row],[Total Campaigns Accepted]]<3,"Occasional Responders","Frequent Responders")) -> Never Responded
A13: 5642 | B13: 1979 | C13: Master | D13: Together | E13: 62499 | F13: 1 | G13: 0 | H13: 41617 | I13: 0 | J13: 140 | K13: 4 | L13: 61 | M13: 0 | N13: 13 | O13: 4 | P13: 2 | Q13: 3 | R13: 1 | S13: 6 | T13: 4 | U13: 0 | V13: 0 | W13: 0 | X13: 0 | Y13: 0 | Z13: 0 | AA13: 0 | AB13: Spain | AC13: =YEAR(TODAY()) - B13 -> 47 | AD13: =SUM(J13:O13) -> 222 | AE13: =SUM(P13:T13) -> 16 | AF13: =IF(Table2[[#This Row],[ Income ]]<=30000, "Low Income",IF(Table2[[#This Row],[ Income ]]<=60000,"Middle Income",IF(Table2[[#This Row],[ Income ]]<=90000,"High Income","Premium"))) -> High Income | AG13: =IF(Table2[[#This Row],[Age]]<30,"Young Adults", IF(Table2[[#This Row],[Age]]<45,"Adults",IF(Table2[[#This Row],[Age]]<60,"Middle Aged", "Senior"))) -> Middle Aged | AH13: =IF(Table2[[#This Row],[Recency]]<31,"Active",IF(Table2[[#This Row],[Recency]]<61, "Warm","At Risk")) -> Active | AI13: =IF(Table2[[#This Row],[Total Spend]]<70,"Low Value", IF(Table2[[#This Row],[Total Spend]]<370,"Medium Value",IF(Table2[[#This Row],[Total Spend]]<1047,"High Value","VIP"))) -> Medium Value | AJ13: =SUM(Table2[[#This Row],[AcceptedCmp3]:[Response]]) -> 0 | AK13: =IF(Table2[[#This Row],[Total Campaigns Accepted]]=0,"Never Responded", IF(Table2[[#This Row],[Total Campaigns Accepted]]<3,"Occasional Responders","Frequent Responders")) -> Never Responded
... A135: 8619 | B135: 1957 | C135: Graduation | D135: Together | E135: 21994 | F135: 0 | G135: 1 | H135: 41267 | I135: 4 | J135: 9 | K135: 0 | L135: 6 | M135: 3 | N135: 1 | O135: 3 | P135: 1 | Q135: 0 | R135: 0 | S135: 3 | T135: 5 | U135: 0 | V135: 0 | W135: 0 | X135: 0 | Y135: 0 | Z135: 0 | AA135: 0 | AB135: Spain | AC135: =YEAR(TODAY()) - B135 -> 69 | AD135: =SUM(J135:O135) -> 22 | AE135: =SUM(P135:T135) -> 9 | AF135: =IF(Table2[[#This Row],[ Income ]]<=30000, "Low Income",IF(Table2[[#This Row],[ Income ]]<=60000,"Middle Income",IF(Table2[[#This Row],[ Income ]]<=90000,"High Income","Premium"))) -> Low Income | AG135: =IF(Table2[[#This Row],[Age]]<30,"Young Adults", IF(Table2[[#This Row],[Age]]<45,"Adults",IF(Table2[[#This Row],[Age]]<60,"Middle Aged", "Senior"))) -> Senior | AH135: =IF(Table2[[#This Row],[Recency]]<31,"Active",IF(Table2[[#This Row],[Recency]]<61, "Warm","At Risk")) -> Active | AI135: =IF(Table2[[#This Row],[Total Spend]]<70,"Low Value", IF(Table2[[#This Row],[Total Spend]]<370,"Medium Value",IF(Table2[[#This Row],[Total Spend]]<1047,"High Value","VIP"))) -> Low Value | AJ135: =SUM(Table2[[#This Row],[AcceptedCmp3]:[Response]]) -> 0 | AK135: =IF(Table2[[#This Row],[Total Campaigns Accepted]]=0,"Never Responded", IF(Table2[[#This Row],[Total Campaigns Accepted]]<3,"Occasional Responders","Frequent Responders")) -> Never Responded
A136: 8996 | B136: 1957 | C136: PhD | D136: Married | F136: 2 | G136: 1 | H136: 41232 | I136: 4 | J136: 230 | K136: 42 | L136: 192 | M136: 49 | N136: 37 | O136: 53 | P136: 12 | Q136: 7 | R136: 2 | S136: 8 | T136: 9 | U136: 0 | V136: 0 | W136: 0 | X136: 0 | Y136: 0 | Z136: 0 | AA136: 0 | AB136: Germany | AC136: =YEAR(TODAY()) - B136 -> 69 | AD136: =SUM(J136:O136) -> 603 | AE136: =SUM(P136:T136) -> 38 | AF136: =IF(Table2[[#This Row],[ Income ]]<=30000, "Low Income",IF(Table2[[#This Row],[ Income ]]<=60000,"Middle Income",IF(Table2[[#This Row],[ Income ]]<=90000,"High Income","Premium"))) -> Low Income | AG136: =IF(Table2[[#This Row],[Age]]<30,"Young Adults", IF(Table2[[#This Row],[Age]]<45,"Adults",IF(Table2[[#This Row],[Age]]<60,"Middle Aged", "Senior"))) -> Senior | AH136: =IF(Table2[[#This Row],[Recency]]<31,"Active",IF(Table2[[#This Row],[Recency]]<61, "Warm","At Risk")) -> Active | AI136: =IF(Table2[[#This Row],[Total Spend]]<70,"Low Value", IF(Table2[[#This Row],[Total Spend]]<370,"Medium Value",IF(Table2[[#This Row],[Total Spend]]<1047,"High Value","VIP"))) -> High Value | AJ136: =SUM(Table2[[#This Row],[AcceptedCmp3]:[Response]]) -> 0 | AK136: =IF(Table2[[#This Row],[Total Campaigns Accepted]]=0,"Never Responded", IF(Table2[[#This Row],[Total Campaigns Accepted]]<3,"Occasional Responders","Frequent Responders")) -> Never Responded
A137: 7233 | B137: 1972 | C137: Graduation | D137: Married | E137: 69209 | F137: 0 | G137: 0 | H137: 41169 | I137: 4 | J137: 496 | K137: 32 | L137: 849 | M137: 229 | N137: 48 | O137: 128 | P137: 2 | Q137: 5 | R137: 3 | S137: 6 | T137: 4 | U137: 0 | V137: 0 | W137: 0 | X137: 1 | Y137: 0 | Z137: 0 | AA137: 0 | AB137: Canada | AC137: =YEAR(TODAY()) - B137 -> 54 | AD137: =SUM(J137:O137) -> 1782 | AE137: =SUM(P137:T137) -> 20 | AF137: =IF(Table2[[#This Row],[ Income ]]<=30000, "Low Income",IF(Table2[[#This Row],[ Income ]]<=60000,"Middle Income",IF(Table2[[#This Row],[ Income ]]<=90000,"High Income","Premium"))) -> High Income | AG137: =IF(Table2[[#This Row],[Age]]<30,"Young Adults", IF(Table2[[#This Row],[Age]]<45,"Adults",IF(Table2[[#This Row],[Age]]<60,"Middle Aged", "Senior"))) -> Middle Aged | AH137: =IF(Table2[[#This Row],[Recency]]<31,"Active",IF(Table2[[#This Row],[Recency]]<61, "Warm","At Risk")) -> Active | AI137: =IF(Table2[[#This Row],[Total Spend]]<70,"Low Value", IF(Table2[[#This Row],[Total Spend]]<370,"Medium Value",IF(Table2[[#This Row],[Total Spend]]<1047,"High Value","VIP"))) -> VIP | AJ137: =SUM(Table2[[#This Row],[AcceptedCmp3]:[Response]]) -> 1 | AK137: =IF(Table2[[#This Row],[Total Campaigns Accepted]]=0,"Never Responded", IF(Table2[[#This Row],[Total Campaigns Accepted]]<3,"Occasional Responders","Frequent Responders")) -> Occasional Responders
A138: 6678 | B138: 1989 | C138: Graduation | D138: Together | E138: 31928 | F138: 1 | G138: 0 | H138: 41726 | I138: 5 | J138: 33 | K138: 4 | L138: 24 | M138: 4 | N138: 2 | O138: 5 | P138: 2 | Q138: 3 | R138: 0 | S138: 4 | T138: 7 | U138: 0 | V138: 0 | W138: 0 | X138: 0 | Y138: 0 | Z138: 0 | AA138: 0 | AB138: India | AC138: =YEAR(TODAY()) - B138 -> 37 | AD138: =SUM(J138:O138) -> 72 | AE138: =SUM(P138:T138) -> 16 | AF138: =IF(Table2[[#This Row],[ Income ]]<=30000, "Low Income",IF(Table2[[#This Row],[ Income ]]<=60000,"Middle Income",IF(Table2[[#This Row],[ Income ]]<=90000,"High Income","Premium"))) -> Middle Income | AG138: =IF(Table2[[#This Row],[Age]]<30,"Young Adults", IF(Table2[[#This Row],[Age]]<45,"Adults",IF(Table2[[#This Row],[Age]]<60,"Middle Aged", "Senior"))) -> Adults | AH138: =IF(Table2[[#This Row],[Recency]]<31,"Active",IF(Table2[[#This Row],[Recency]]<61, "Warm","At Risk")) -> Active | AI138: =IF(Table2[[#This Row],[Total Spend]]<70,"Low Value", IF(Table2[[#This Row],[Total Spend]]<370,"Medium Value",IF(Table2[[#This Row],[Total Spend]]<1047,"High Value","VIP"))) -> Medium Value | AJ138: =SUM(Table2[[#This Row],[AcceptedCmp3]:[Response]]) -> 0 | AK138: =IF(Table2[[#This Row],[Total Campaigns Accepted]]=0,"Never Responded", IF(Table2[[#This Row],[Total Campaigns Accepted]]<3,"Occasional Responders","Frequent Responders")) -> Never Responded
A139: 830 | B139: 1987 | C139: PhD | D139: Single | E139: 74004 | F139: 0 | G139: 0 | H139: 41694 | I139: 5 | J139: 784 | K139: 48 | L139: 560 | M139: 42 | N139: 176 | O139: 48 | P139: 1 | Q139: 4 | R139: 6 | S139: 4 | T139: 3 | U139: 0 | V139: 0 | W139: 1 | X139: 1 | Y139: 0 | Z139: 1 | AA139: 0 | AB139: India | AC139: =YEAR(TODAY()) - B139 -> 39 | AD139: =SUM(J139:O139) -> 1658 | AE139: =SUM(P139:T139) -> 18 | AF139: =IF(Table2[[#This Row],[ Income ]]<=30000, "Low Income",IF(Table2[[#This Row],[ Income ]]<=60000,"Middle Income",IF(Table2[[#This Row],[ Income ]]<=90000,"High Income","Premium"))) -> High Income | AG139: =IF(Table2[[#This Row],[Age]]<30,"Young Adults", IF(Table2[[#This Row],[Age]]<45,"Adults",IF(Table2[[#This Row],[Age]]<60,"Middle Aged", "Senior"))) -> Adults | AH139: =IF(Table2[[#This Row],[Recency]]<31,"Active",IF(Table2[[#This Row],[Recency]]<61, "Warm","At Risk")) -> Active | AI139: =IF(Table2[[#This Row],[Total Spend]]<70,"Low Value", IF(Table2[[#This Row],[Total Spend]]<370,"Medium Value",IF(Table2[[#This Row],[Total Spend]]<1047,"High Value","VIP"))) -> VIP | AJ139: =SUM(Table2[[#This Row],[AcceptedCmp3]:[Response]]) -> 3 | AK139: =IF(Table2[[#This Row],[Total Campaigns Accepted]]=0,"Never Responded", IF(Table2[[#This Row],[Total Campaigns Accepted]]<3,"Occasional Responders","Frequent Responders")) -> Frequent Responders
A140: 6365 | B140: 1987 | C140: 2n Cycle | D140: Married | E140: 30390 | F140: 0 | G140: 0 | H140: 41519 | I140: 5 | J140: 10 | K140: 12 | L140: 12 | M140: 25 | N140: 1 | O140: 20 | P140: 1 | Q140: 2 | R140: 0 | S140: 3 | T140: 6 | U140: 0 | V140: 0 | W140: 0 | X140: 0 | Y140: 0 | Z140: 0 | AA140: 0 | AB140: India | AC140: =YEAR(TODAY()) - B140 -> 39 | AD140: =SUM(J140:O140) -> 80 | AE140: =SUM(P140:T140) -> 12 | AF140: =IF(Table2[[#This Row],[ Income ]]<=30000, "Low Income",IF(Table2[[#This Row],[ Income ]]<=60000,"Middle Income",IF(Table2[[#This Row],[ Income ]]<=90000,"High Income","Premium"))) -> Middle Income | AG140: =IF(Table2[[#This Row],[Age]]<30,"Young Adults", IF(Table2[[#This Row],[Age]]<45,"Adults",IF(Table2[[#This Row],[Age]]<60,"Middle Aged", "Senior"))) -> Adults | AH140: =IF(Table2[[#This Row],[Recency]]<31,"Active",IF(Table2[[#This Row],[Recency]]<61, "Warm","At Risk")) -> Active | AI140: =IF(Table2[[#This Row],[Total Spend]]<70,"Low Value", IF(Table2[[#This Row],[Total Spend]]<370,"Medium Value",IF(Table2[[#This Row],[Total Spend]]<1047,"High Value","VIP"))) -> Medium Value | AJ140: =SUM(Table2[[#This Row],[AcceptedCmp3]:[Response]]) -> 0 | AK140: =IF(Table2[[#This Row],[Total Campaigns Accepted]]=0,"Never Responded", IF(Table2[[#This Row],[Total Campaigns Accepted]]<3,"Occasional Responders","Frequent Responders")) -> Never Responded
A141: 6770 | B141: 1985 | C141: Graduation | D141: Married | E141: 21355 | F141: 1 | G141: 0 | H141: 41506 | I141: 5 | J141: 5 | K141: 13 | L141: 14 | M141: 0 | N141: 5 | O141: 31 | P141: 2 | Q141: 2 | R141: 1 | S141: 2 | T141: 6 | U141: 1 | V141: 0 | W141: 0 | X141: 0 | Y141: 0 | Z141: 1 | AA141: 0 | AB141: USA | AC141: =YEAR(TODAY()) - B141 -> 41 | AD141: =SUM(J141:O141) -> 68 | AE141: =SUM(P141:T141) -> 13 | AF141: =IF(Table2[[#This Row],[ Income ]]<=30000, "Low Income",IF(Table2[[#This Row],[ Income ]]<=60000,"Middle Income",IF(Table2[[#This Row],[ Income ]]<=90000,"High Income","Premium"))) -> Low Income | AG141: =IF(Table2[[#This Row],[Age]]<30,"Young Adults", IF(Table2[[#This Row],[Age]]<45,"Adults",IF(Table2[[#This Row],[Age]]<60,"Middle Aged", "Senior"))) -> Adults | AH141: =IF(Table2[[#This Row],[Recency]]<31,"Active",IF(Table2[[#This Row],[Recency]]<61, "Warm","At Risk")) -> Active | AI141: =IF(Table2[[#This Row],[Total Spend]]<70,"Low Value", IF(Table2[[#This Row],[Total Spend]]<370,"Medium Value",IF(Table2[[#This Row],[Total Spend]]<1047,"High Value","VIP"))) -> Low Value | AJ141: =SUM(Table2[[#This Row],[AcceptedCmp3]:[Response]]) -> 2 | AK141: =IF(Table2[[#This Row],[Total Campaigns Accepted]]=0,"Never Responded", IF(Table2[[#This Row],[Total Campaigns Accepted]]<3,"Occasional Responders","Frequent Responders")) -> Occasional Responders
A142: 2261 | B142: 1969 | C142: Graduation | D142: Married | E142: 26304 | F142: 1 | G142: 0 | H142: 41448 | I142: 5 | J142: 4 | K142: 1 | L142: 5 | M142: 2 | N142: 0 | O142: 4 | P142: 1 | Q142: 1 | R142: 0 | S142: 2 | T142: 7 | U142: 0 | V142: 0 | W142: 0 | X142: 0 | Y142: 0 | Z142: 0 | AA142: 0 | AB142: Germany | AC142: =YEAR(TODAY()) - B142 -> 57 | AD142: =SUM(J142:O142) -> 16 | AE142: =SUM(P142:T142) -> 11 | AF142: =IF(Table2[[#This Row],[ Income ]]<=30000, "Low Income",IF(Table2[[#This Row],[ Income ]]<=60000,"Middle Income",IF(Table2[[#This Row],[ Income ]]<=90000,"High Income","Premium"))) -> Low Income | AG142: =IF(Table2[[#This Row],[Age]]<30,"Young Adults", IF(Table2[[#This Row],[Age]]<45,"Adults",IF(Table2[[#This Row],[Age]]<60,"Middle Aged", "Senior"))) -> Middle Aged | AH142: =IF(Table2[[#This Row],[Recency]]<31,"Active",IF(Table2[[#This Row],[Recency]]<61, "Warm","At Risk")) -> Active | AI142: =IF(Table2[[#This Row],[Total Spend]]<70,"Low Value", IF(Table2[[#This Row],[Total Spend]]<370,"Medium Value",IF(Table2[[#This Row],[Total Spend]]<1047,"High Value","VIP"))) -> Low Value | AJ142: =SUM(Table2[[#This Row],[AcceptedCmp3]:[Response]]) -> 0 | AK142: =IF(Table2[[#This Row],[Total Campaigns Accepted]]=0,"Never Responded", IF(Table2[[#This Row],[Total Campaigns Accepted]]<3,"Occasional Responders","Frequent Responders")) -> Never Responded
A143: 1031 | B143: 1989 | C143: 2n Cycle | D143: Married | E143: 85710 | F143: 0 | G143: 0 | H143: 41399 | I143: 5 | J143: 600 | K143: 20 | L143: 350 | M143: 29 | N143: 30 | O143: 33 | P143: 1 | Q143: 6 | R143: 9 | S143: 10 | T143: 2 | U143: 0 | V143: 0 | W143: 1 | X143: 0 | Y143: 0 | Z143: 0 | AA143: 0 | AB143: India | AC143: =YEAR(TODAY()) - B143 -> 37 | AD143: =SUM(J143:O143) -> 1062 | AE143: =SUM(P143:T143) -> 28 | AF143: =IF(Table2[[#This Row],[ Income ]]<=30000, "Low Income",IF(Table2[[#This Row],[ Income ]]<=60000,"Middle Income",IF(Table2[[#This Row],[ Income ]]<=90000,"High Income","Premium"))) -> High Income | AG143: =IF(Table2[[#This Row],[Age]]<30,"Young Adults", IF(Table2[[#This Row],[Age]]<45,"Adults",IF(Table2[[#This Row],[Age]]<60,"Middle Aged", "Senior"))) -> Adults | AH143: =IF(Table2[[#This Row],[Recency]]<31,"Active",IF(Table2[[#This Row],[Recency]]<61, "Warm","At Risk")) -> Active | AI143: =IF(Table2[[#This Row],[Total Spend]]<70,"Low Value", IF(Table2[[#This Row],[Total Spend]]<370,"Medium Value",IF(Table2[[#This Row],[Total Spend]]<1047,"High Value","VIP"))) -> VIP | AJ143: =SUM(Table2[[#This Row],[AcceptedCmp3]:[Response]]) -> 1 | AK143: =IF(Table2[[#This Row],[Total Campaigns Accepted]]=0,"Never Responded", IF(Table2[[#This Row],[Total Campaigns Accepted]]<3,"Occasional Responders","Frequent Responders")) -> Occasional Responders
A144: 10089 | B144: 1974 | C144: Graduation | D144: Divorced | E144: 102692 | F144: 0 | G144: 0 | H144: 41369 | I144: 5 | J144: 168 | K144: 148 | L144: 444 | M144: 32 | N144: 172 | O144: 148 | P144: 1 | Q144: 6 | R144: 9 | S144: 13 | T144: 2 | U144: 0 | V144: 1 | W144: 1 | X144: 1 | Y144: 1 | Z144: 1 | AA144: 0 | AB144: Saudi Arabia | AC144: =YEAR(TODAY()) - B144 -> 52 | AD144: =SUM(J144:O144) -> 1112 | AE144: =SUM(P144:T144) -> 31 | AF144: =IF(Table2[[#This Row],[ Income ]]<=30000, "Low Income",IF(Table2[[#This Row],[ Income ]]<=60000,"Middle Income",IF(Table2[[#This Row],[ Income ]]<=90000,"High Income","Premium"))) -> Premium | AG144: =IF(Table2[[#This Row],[Age]]<30,"Young Adults", IF(Table2[[#This Row],[Age]]<45,"Adults",IF(Table2[[#This Row],[Age]]<60,"Middle Aged", "Senior"))) -> Middle Aged | AH144: =IF(Table2[[#This Row],[Recency]]<31,"Active",IF(Table2[[#This Row],[Recency]]<61, "Warm","At Risk")) -> Active | AI144: =IF(Table2[[#This Row],[Total Spend]]<70,"Low Value", IF(Table2[[#This Row],[Total Spend]]<370,"Medium Value",IF(Table2[[#This Row],[Total Spend]]<1047,"High Value","VIP"))) -> VIP | AJ144: =SUM(Table2[[#This Row],[AcceptedCmp3]:[Response]]) -> 5 | AK144: =IF(Table2[[#This Row],[Total Campaigns Accepted]]=0,"Never Responded", IF(Table2[[#This Row],[Total Campaigns Accepted]]<3,"Occasional Responders","Frequent Responders")) -> Frequent Responders
A145: 9256 | B145: 1971 | C145: Graduation | D145: Single | E145: 58350 | F145: 0 | G145: 1 | H145: 41278 | I145: 5 | J145: 493 | K145: 26 | L145: 206 | M145: 116 | N145: 80 | O145: 80 | P145: 4 | Q145: 8 | R145: 3 | S145: 12 | T145: 6 | U145: 0 | V145: 0 | W145: 0 | X145: 0 | Y145: 0 | Z145: 0 | AA145: 0 | AB145: Spain | AC145: =YEAR(TODAY()) - B145 -> 55 | AD145: =SUM(J145:O145) -> 1001 | AE145: =SUM(P145:T145) -> 33 | AF145: =IF(Table2[[#This Row],[ Income ]]<=30000, "Low Income",IF(Table2[[#This Row],[ Income ]]<=60000,"Middle Income",IF(Table2[[#This Row],[ Income ]]<=90000,"High Income","Premium"))) -> Middle Income | AG145: =IF(Table2[[#This Row],[Age]]<30,"Young Adults", IF(Table2[[#This Row],[Age]]<45,"Adults",IF(Table2[[#This Row],[Age]]<60,"Middle Aged", "Senior"))) -> Middle Aged | AH145: =IF(Table2[[#This Row],[Recency]]<31,"Active",IF(Table2[[#This Row],[Recency]]<61, "Warm","At Risk")) -> Active | AI145: =IF(Table2[[#This Row],[Total Spend]]<70,"Low Value", IF(Table2[[#This Row],[Total Spend]]<370,"Medium Value",IF(Table2[[#This Row],[Total Spend]]<1047,"High Value","VIP"))) -> High Value | AJ145: =SUM(Table2[[#This Row],[AcceptedCmp3]:[Response]]) -> 0 | AK145: =IF(Table2[[#This Row],[Total Campaigns Accepted]]=0,"Never Responded", IF(Table2[[#This Row],[Total Campaigns Accepted]]<3,"Occasional Responders","Frequent Responders")) -> Never Responded
A146: 10641 | B146: 1978 | C146: Graduation | D146: Single | E146: 7500 | F146: 1 | G146: 1 | H146: 41270 | I146: 5 | J146: 6 | K146: 5 | L146: 4 | M146: 13 | N146: 4 | O146: 25 | P146: 4 | Q146: 2 | R146: 1 | S146: 3 | T146: 6 | U146: 0 | V146: 0 | W146: 0 | X146: 0 | Y146: 0 | Z146: 0 | AA146: 0 | AB146: Spain | AC146: =YEAR(TODAY()) - B146 -> 48 | AD146: =SUM(J146:O146) -> 57 | AE146: =SUM(P146:T146) -> 16 | AF146: =IF(Table2[[#This Row],[ Income ]]<=30000, "Low Income",IF(Table2[[#This Row],[ Income ]]<=60000,"Middle Income",IF(Table2[[#This Row],[ Income ]]<=90000,"High Income","Premium"))) -> Low Income | AG146: =IF(Table2[[#This Row],[Age]]<30,"Young Adults", IF(Table2[[#This Row],[Age]]<45,"Adults",IF(Table2[[#This Row],[Age]]<60,"Middle Aged", "Senior"))) -> Middle Aged | AH146: =IF(Table2[[#This Row],[Recency]]<31,"Active",IF(Table2[[#This Row],[Recency]]<61, "Warm","At Risk")) -> Active | AI146: =IF(Table2[[#This Row],[Total Spend]]<70,"Low Value", IF(Table2[[#This Row],[Total Spend]]<370,"Medium Value",IF(Table2[[#This Row],[Total Spend]]<1047,"High Value","VIP"))) -> Low Value | AJ146: =SUM(Table2[[#This Row],[AcceptedCmp3]:[Response]]) -> 0 | AK146: =IF(Table2[[#This Row],[Total Campaigns Accepted]]=0,"Never Responded", IF(Table2[[#This Row],[Total Campaigns Accepted]]<3,"Occasional Responders","Frequent Responders")) -> Never Responded
A147: 624 | B147: 1984 | C147: Master | D147: Single | E147: 18890 | F147: 0 | G147: 0 | H147: 41223 | I147: 5 | J147: 6 | K147: 4 | L147: 1 | M147: 7 | N147: 2 | O147: 15 | P147: 1 | Q147: 0 | R147: 1 | S147: 2 | T147: 6 | U147: 1 | V147: 0 | W147: 0 | X147: 0 | Y147: 0 | Z147: 1 | AA147: 0 | AB147: Saudi Arabia | AC147: =YEAR(TODAY()) - B147 -> 42 | AD147: =SUM(J147:O147) -> 35 | AE147: =SUM(P147:T147) -> 10 | AF147: =IF(Table2[[#This Row],[ Income ]]<=30000, "Low Income",IF(Table2[[#This Row],[ Income ]]<=60000,"Middle Income",IF(Table2[[#This Row],[ Income ]]<=90000,"High Income","Premium"))) -> Low Income | AG147: =IF(Table2[[#This Row],[Age]]<30,"Young Adults", IF(Table2[[#This Row],[Age]]<45,"Adults",IF(Table2[[#This Row],[Age]]<60,"Middle Aged", "Senior"))) -> Adults | AH147: =IF(Table2[[#This Row],[Recency]]<31,"Active",IF(Table2[[#This Row],[Recency]]<61, "Warm","At Risk")) -> Active | AI147: =IF(Table2[[#This Row],[Total Spend]]<70,"Low Value", IF(Table2[[#This Row],[Total Spend]]<370,"Medium Value",IF(Table2[[#This Row],[Total Spend]]<1047,"High Value","VIP"))) -> Low Value | AJ147: =SUM(Table2[[#This Row],[AcceptedCmp3]:[Response]]) -> 2 | AK147: =IF(Table2[[#This Row],[Total Campaigns Accepted]]=0,"Never Responded", IF(Table2[[#This Row],[Total Campaigns Accepted]]<3,"Occasional Responders","Frequent Responders")) -> Occasional Responders
A148: 4211 | B148: 1986 | C148: Basic | D148: Married | E148: 20425 | F148: 1 | G148: 0 | H148: 41211 | I148: 5 | J148: 4 | K148: 12 | L148: 5 | M148: 3 | N148: 16 | O148: 17 | P148: 2 | Q148: 2 | R148: 0 | S148: 3 | T148: 7 | U148: 0 | V148: 0 | W148: 0 | X148: 0 | Y148: 0 | Z148: 0 | AA148: 0 | AB148: Canada | AC148: =YEAR(TODAY()) - B148 -> 40 | AD148: =SUM(J148:O148) -> 57 | AE148: =SUM(P148:T148) -> 14 | AF148: =IF(Table2[[#This Row],[ Income ]]<=30000, "Low Income",IF(Table2[[#This Row],[ Income ]]<=60000,"Middle Income",IF(Table2[[#This Row],[ Income ]]<=90000,"High Income","Premium"))) -> Low Income | AG148: =IF(Table2[[#This Row],[Age]]<30,"Young Adults", IF(Table2[[#This Row],[Age]]<45,"Adults",IF(Table2[[#This Row],[Age]]<60,"Middle Aged", "Senior"))) -> Adults | AH148: =IF(Table2[[#This Row],[Recency]]<31,"Active",IF(Table2[[#This Row],[Recency]]<61, "Warm","At Risk")) -> Active | AI148: =IF(Table2[[#This Row],[Total Spend]]<70,"Low Value", IF(Table2[[#This Row],[Total Spend]]<370,"Medium Value",IF(Table2[[#This Row],[Total Spend]]<1047,"High Value","VIP"))) -> Low Value | AJ148: =SUM(Table2[[#This Row],[AcceptedCmp3]:[Response]]) -> 0 | AK148: =IF(Table2[[#This Row],[Total Campaigns Accepted]]=0,"Never Responded", IF(Table2[[#This Row],[Total Campaigns Accepted]]<3,"Occasional Responders","Frequent Responders")) -> Never Responded
... A263: 11191 | B263: 1986 | C263: Graduation | D263: Divorced | E263: 41411 | F263: 0 | G263: 0 | H263: 41615 | I263: 11 | J263: 37 | K263: 32 | L263: 38 | M263: 11 | N263: 3 | O263: 18 | P263: 1 | Q263: 2 | R263: 1 | S263: 4 | T263: 6 | U263: 0 | V263: 0 | W263: 0 | X263: 0 | Y263: 0 | Z263: 0 | AA263: 0 | AB263: Spain | AC263: =YEAR(TODAY()) - B263 -> 40 | AD263: =SUM(J263:O263) -> 139 | AE263: =SUM(P263:T263) -> 14 | AF263: =IF(Table2[[#This Row],[ Income ]]<=30000, "Low Income",IF(Table2[[#This Row],[ Income ]]<=60000,"Middle Income",IF(Table2[[#This Row],[ Income ]]<=90000,"High Income","Premium"))) -> Middle Income | AG263: =IF(Table2[[#This Row],[Age]]<30,"Young Adults", IF(Table2[[#This Row],[Age]]<45,"Adults",IF(Table2[[#This Row],[Age]]<60,"Middle Aged", "Senior"))) -> Adults | AH263: =IF(Table2[[#This Row],[Recency]]<31,"Active",IF(Table2[[#This Row],[Recency]]<61, "Warm","At Risk")) -> Active | AI263: =IF(Table2[[#This Row],[Total Spend]]<70,"Low Value", IF(Table2[[#This Row],[Total Spend]]<370,"Medium Value",IF(Table2[[#This Row],[Total Spend]]<1047,"High Value","VIP"))) -> Medium Value | AJ263: =SUM(Table2[[#This Row],[AcceptedCmp3]:[Response]]) -> 0 | AK263: =IF(Table2[[#This Row],[Total Campaigns Accepted]]=0,"Never Responded", IF(Table2[[#This Row],[Total Campaigns Accepted]]<3,"Occasional Responders","Frequent Responders")) -> Never Responded
A264: 1994 | B264: 1983 | C264: Graduation | D264: Married | F264: 1 | G264: 0 | H264: 41593 | I264: 11 | J264: 5 | K264: 5 | L264: 6 | M264: 0 | N264: 2 | O264: 1 | P264: 1 | Q264: 1 | R264: 0 | S264: 2 | T264: 7 | U264: 0 | V264: 0 | W264: 0 | X264: 0 | Y264: 0 | Z264: 0 | AA264: 0 | AB264: USA | AC264: =YEAR(TODAY()) - B264 -> 43 | AD264: =SUM(J264:O264) -> 19 | AE264: =SUM(P264:T264) -> 11 | AF264: =IF(Table2[[#This Row],[ Income ]]<=30000, "Low Income",IF(Table2[[#This Row],[ Income ]]<=60000,"Middle Income",IF(Table2[[#This Row],[ Income ]]<=90000,"High Income","Premium"))) -> Low Income | AG264: =IF(Table2[[#This Row],[Age]]<30,"Young Adults", IF(Table2[[#This Row],[Age]]<45,"Adults",IF(Table2[[#This Row],[Age]]<60,"Middle Aged", "Senior"))) -> Adults | AH264: =IF(Table2[[#This Row],[Recency]]<31,"Active",IF(Table2[[#This Row],[Recency]]<61, "Warm","At Risk")) -> Active | AI264: =IF(Table2[[#This Row],[Total Spend]]<70,"Low Value", IF(Table2[[#This Row],[Total Spend]]<370,"Medium Value",IF(Table2[[#This Row],[Total Spend]]<1047,"High Value","VIP"))) -> Low Value | AJ264: =SUM(Table2[[#This Row],[AcceptedCmp3]:[Response]]) -> 0 | AK264: =IF(Table2[[#This Row],[Total Campaigns Accepted]]=0,"Never Responded", IF(Table2[[#This Row],[Total Campaigns Accepted]]<3,"Occasional Responders","Frequent Responders")) -> Never Responded
A265: 2552 | B265: 1955 | C265: PhD | D265: Single | E265: 55521 | F265: 1 | G265: 2 | H265: 41569 | I265: 11 | J265: 416 | K265: 0 | L265: 26 | M265: 0 | N265: 0 | O265: 4 | P265: 9 | Q265: 6 | R265: 3 | S265: 6 | T265: 7 | U265: 0 | V265: 1 | W265: 0 | X265: 0 | Y265: 0 | Z265: 1 | AA265: 0 | AB265: Spain | AC265: =YEAR(TODAY()) - B265 -> 71 | AD265: =SUM(J265:O265) -> 446 | AE265: =SUM(P265:T265) -> 31 | AF265: =IF(Table2[[#This Row],[ Income ]]<=30000, "Low Income",IF(Table2[[#This Row],[ Income ]]<=60000,"Middle Income",IF(Table2[[#This Row],[ Income ]]<=90000,"High Income","Premium"))) -> Middle Income | AG265: =IF(Table2[[#This Row],[Age]]<30,"Young Adults", IF(Table2[[#This Row],[Age]]<45,"Adults",IF(Table2[[#This Row],[Age]]<60,"Middle Aged", "Senior"))) -> Senior | AH265: =IF(Table2[[#This Row],[Recency]]<31,"Active",IF(Table2[[#This Row],[Recency]]<61, "Warm","At Risk")) -> Active | AI265: =IF(Table2[[#This Row],[Total Spend]]<70,"Low Value", IF(Table2[[#This Row],[Total Spend]]<370,"Medium Value",IF(Table2[[#This Row],[Total Spend]]<1047,"High Value","VIP"))) -> High Value | AJ265: =SUM(Table2[[#This Row],[AcceptedCmp3]:[Response]]) -> 2 | AK265: =IF(Table2[[#This Row],[Total Campaigns Accepted]]=0,"Never Responded", IF(Table2[[#This Row],[Total Campaigns Accepted]]<3,"Occasional Responders","Frequent Responders")) -> Occasional Responders
A266: 6720 | B266: 1968 | C266: Master | D266: Together | E266: 43795 | F266: 0 | G266: 1 | H266: 41563 | I266: 11 | J266: 314 | K266: 11 | L266: 53 | M266: 4 | N266: 3 | O266: 107 | P266: 3 | Q266: 7 | R266: 3 | S266: 4 | T266: 7 | U266: 0 | V266: 1 | W266: 0 | X266: 0 | Y266: 0 | Z266: 1 | AA266: 0 | AB266: Spain | AC266: =YEAR(TODAY()) - B266 -> 58 | AD266: =SUM(J266:O266) -> 492 | AE266: =SUM(P266:T266) -> 24 | AF266: =IF(Table2[[#This Row],[ Income ]]<=30000, "Low Income",IF(Table2[[#This Row],[ Income ]]<=60000,"Middle Income",IF(Table2[[#This Row],[ Income ]]<=90000,"High Income","Premium"))) -> Middle Income | AG266: =IF(Table2[[#This Row],[Age]]<30,"Young Adults", IF(Table2[[#This Row],[Age]]<45,"Adults",IF(Table2[[#This Row],[Age]]<60,"Middle Aged", "Senior"))) -> Middle Aged | AH266: =IF(Table2[[#This Row],[Recency]]<31,"Active",IF(Table2[[#This Row],[Recency]]<61, "Warm","At Risk")) -> Active | AI266: =IF(Table2[[#This Row],[Total Spend]]<70,"Low Value", IF(Table2[[#This Row],[Total Spend]]<370,"Medium Value",IF(Table2[[#This Row],[Total Spend]]<1047,"High Value","VIP"))) -> High Value | AJ266: =SUM(Table2[[#This Row],[AcceptedCmp3]:[Response]]) -> 2 | AK266: =IF(Table2[[#This Row],[Total Campaigns Accepted]]=0,"Never Responded", IF(Table2[[#This Row],[Total Campaigns Accepted]]<3,"Occasional Responders","Frequent Responders")) -> Occasional Responders
A267: 4557 | B267: 1970 | C267: Graduation | D267: Together | E267: 22070 | F267: 1 | G267: 0 | H267: 41551 | I267: 11 | J267: 10 | K267: 7 | L267: 19 | M267: 8 | N267: 2 | O267: 21 | P267: 2 | Q267: 2 | R267: 2 | S267: 2 | T267: 6 | U267: 0 | V267: 0 | W267: 0 | X267: 0 | Y267: 0 | Z267: 0 | AA267: 0 | AB267: Saudi Arabia | AC267: =YEAR(TODAY()) - B267 -> 56 | AD267: =SUM(J267:O267) -> 67 | AE267: =SUM(P267:T267) -> 14 | AF267: =IF(Table2[[#This Row],[ Income ]]<=30000, "Low Income",IF(Table2[[#This Row],[ Income ]]<=60000,"Middle Income",IF(Table2[[#This Row],[ Income ]]<=90000,"High Income","Premium"))) -> Low Income | AG267: =IF(Table2[[#This Row],[Age]]<30,"Young Adults", IF(Table2[[#This Row],[Age]]<45,"Adults",IF(Table2[[#This Row],[Age]]<60,"Middle Aged", "Senior"))) -> Middle Aged | AH267: =IF(Table2[[#This Row],[Recency]]<31,"Active",IF(Table2[[#This Row],[Recency]]<61, "Warm","At Risk")) -> Active | AI267: =IF(Table2[[#This Row],[Total Spend]]<70,"Low Value", IF(Table2[[#This Row],[Total Spend]]<370,"Medium Value",IF(Table2[[#This Row],[Total Spend]]<1047,"High Value","VIP"))) -> Low Value | AJ267: =SUM(Table2[[#This Row],[AcceptedCmp3]:[Response]]) -> 0 | AK267: =IF(Table2[[#This Row],[Total Campaigns Accepted]]=0,"Never Responded", IF(Table2[[#This Row],[Total Campaigns Accepted]]<3,"Occasional Responders","Frequent Responders")) -> Never Responded
